<?xml version="1.0" ?>
<!-- =================================================================================== -->
<!-- |    This document was autogenerated by xacro from iiwa7.xacro                    | -->
<!-- |    EDITING THIS FILE BY HAND IS NOT RECOMMENDED                                 | -->
<!-- =================================================================================== -->
<!-- Kuka iiwa 7DoF manipulator -->
<robot name="iiwa" xmlns:controller="http://playerstage.sourceforge.net/gazebo/xmlschema/#controller" xmlns:interface="http://playerstage.sourceforge.net/gazebo/xmlschema/#interface" xmlns:sensor="http://playerstage.sourceforge.net/gazebo/xmlschema/#sensor">
  <!-- Used for fixing robot -->
  <link name="world"/>
  <gazebo reference="world">
    <static>true</static>
  </gazebo>
  <joint name="world_iiwa7_table_base_table_joint" type="fixed">
    <origin rpy="0 0 0" xyz="0 0 1"/>
    <parent link="world"/>
    <child link="iiwa7_table_base"/>
  </joint>
  <!-- BASE LINK -->
  <link name="iiwa7_table_base">
    <inertial>
      <mass value="80"/>
      <origin rpy="1.5707963267948966 0 -1.5707963267948966" xyz="0 0 -0.53"/>
      <inertia ixx="9.874753333333333" ixy="0.0" ixz="0.0" iyy="9.754893333333335" iyz="0.0" izz="6.376193333333333"/>
    </inertial>
    <visual>
      <origin rpy="1.5707963267948966 0 -1.5707963267948966" xyz="0 0 -0.53"/>
      <geometry>
        <mesh filename="package://iiwa7_description/meshes/lf044_rough.dae" scale="0.001 0.001 0.001"/>
      </geometry>
      <material name="grey">
        <color rgba="0.5 0.5 0.5 1"/>
      </material>
    </visual>
    <collision>
      <origin rpy="1.5707963267948966 0 -1.5707963267948966" xyz="0 0 -0.53"/>
      <geometry>
        <mesh filename="package://iiwa7_description/meshes/lf044_rough.stl" scale="0.001 0.001 0.001"/>
      </geometry>
    </collision>
  </link>
  <gazebo reference="iiwa7_table_base">
    <material>Gazebo/Grey</material>
    <gravity>true</gravity>
    <selfCollide>false</selfCollide>
    <mu1>0.3</mu1>
    <mu2>0.3</mu2>
  </gazebo>
  <joint name="table_ee_joint" type="fixed">
    <origin rpy="0 0 0" xyz="0 0 -0.015"/>
    <parent link="iiwa7_table_base"/>
    <child link="table_ee"/>
  </joint>
  <link name="table_ee">
    <visual>
      <geometry>
        <box size="0.2 0.2 0.03"/>
      </geometry>
      <origin rpy="0 0 0" xyz="0 0 0"/>
      <material name="white">
        <color rgba="1.0 1.0 1.0 1.0"/>
      </material>
    </visual>
    <collision>
      <origin rpy="0 0 0" xyz="0 0 0"/>
      <geometry>
        <box size="0.2 0.2 0.2"/>
      </geometry>
    </collision>
    <inertial>
      <origin rpy="0 0 0" xyz="0 0 0"/>
      <mass value="1"/>
      <inertia ixx="0.1" ixy="0.0" ixz="0.0" iyy="0.1" iyz="0.0" izz="0.1"/>
    </inertial>
  </link>
  <gazebo reference="table_ee">
    <material>Gazebo/Black</material>
    <gravity>true</gravity>
    <selfCollide>false</selfCollide>
    <mu1>0.3</mu1>
    <mu2>0.3</mu2>
  </gazebo>
  <joint name="world_conveyor_joint" type="fixed">
    <origin rpy="0 0 1.57" xyz="-1 -5.5 1"/>
    <parent link="world"/>
    <child link="conveyor_system_link"/>
  </joint>
  <!-- BASE LINK -->
  <link name="conveyor_system_link">
    <inertial>
      <mass value="100"/>
      <origin xyz="0 0 0"/>
      <inertia ixx="1" ixy="0.0" ixz="0.0" iyy="1" iyz="0.0" izz="1"/>
    </inertial>
    <visual>
      <!--origin rpy="0 0 0" xyz="0.0 0 -${0.99613/2}"/-->
      <origin rpy="0 0 0" xyz="0 0 0"/>
      <geometry>
        <mesh filename="package://iiwa7_description/meshes/conveyor/visual/bandumlaufsystem.dae" scale="0.001 0.001 0.001"/>
      </geometry>
      <material name="darkgray">
        <color rgba="0.3 0.3 0.3 1.0"/>
      </material>
    </visual>
    <collision>
      <origin rpy="0 0 0" xyz="0 0 0"/>
      <geometry>
        <mesh filename="package://iiwa7_description/meshes/conveyor/collision/bandumlaufsystem.stl" scale="0.001 0.001 0.001"/>
      </geometry>
    </collision>
  </link>
  <gazebo reference="conveyor_system_link">
    <material>Gazebo/Black</material>
    <gravity>true</gravity>
    <mu1>0.5</mu1>
    <mu2>0.4</mu2>
  </gazebo>
  <link name="display">
    <inertial>
      <mass value="100"/>
      <origin xyz="0 0 0"/>
      <inertia ixx="1" ixy="0.0" ixz="0.0" iyy="1" iyz="0.0" izz="1"/>
    </inertial>
    <visual>
      <origin rpy="0 0 0" xyz="0 0 0"/>
      <geometry>
        <box size="0.55 0.01 0.67"/>
      </geometry>
      <material name="white">
        <color rgba="1.0 1.0 1.0 1.0"/>
      </material>
    </visual>
    <collision>
      <origin rpy="0 0 0" xyz="0 0 0"/>
      <geometry>
        <box size="0.55 0.01 0.67"/>
      </geometry>
    </collision>
  </link>
  <joint name="world_display_joint" type="fixed">
    <parent link="world"/>
    <child link="display"/>
    <origin xyz="0 -0.6 1.335"/>
  </joint>
  <joint name="world_hochregallager_joint" type="fixed">
    <origin rpy="0 0 3.14159" xyz="0.80 -0.165 0"/>
    <parent link="world"/>
    <child link="hochregallager_link"/>
  </joint>
  <!-- BASE LINK -->
  <link name="hochregallager_link">
    <inertial>
      <mass value="100"/>
      <origin xyz="0 0 0"/>
      <inertia ixx="1" ixy="0.0" ixz="0.0" iyy="1" iyz="0.0" izz="1"/>
    </inertial>
    <visual>
      <!--origin rpy="0 0 0" xyz="0.0 0 -${0.99613/2}"/-->
      <origin rpy="0 0 0" xyz="0 0 0"/>
      <geometry>
        <mesh filename="package://iiwa7_description/meshes/hochregallager/visual/Hochregallager_Aufbau.dae"/>
      </geometry>
      <material name="darkgray">
        <color rgba="0.3 0.3 0.3 1.0"/>
      </material>
    </visual>
    <collision>
      <origin rpy="0 0 0" xyz="0 0 0"/>
      <geometry>
        <mesh filename="package://iiwa7_description/meshes/hochregallager/collision/Hochregallager_Aufbau.stl"/>
      </geometry>
    </collision>
  </link>
  <gazebo reference="hochregallager_link">
    <material>Gazebo/Black</material>
    <gravity>true</gravity>
    <mu1>0.5</mu1>
    <mu2>0.4</mu2>
  </gazebo>
  <link name="display_regal">
    <inertial>
      <mass value="100"/>
      <origin xyz="0 0 0"/>
      <inertia ixx="1" ixy="0.0" ixz="0.0" iyy="1" iyz="0.0" izz="1"/>
    </inertial>
    <visual>
      <origin rpy="0 0 0" xyz="0 0 0"/>
      <geometry>
        <box size="0.65 0.01 0.75"/>
      </geometry>
      <material name="white">
        <color rgba="1.0 1.0 1.0 1.0"/>
      </material>
    </visual>
    <collision>
      <origin rpy="0 0 0" xyz="0 0 0"/>
      <geometry>
        <box size="0.65 0.01 0.75"/>
      </geometry>
    </collision>
  </link>
  <joint name="hochregallager_display_joint" type="fixed">
    <parent link="hochregallager_link"/>
    <child link="display_regal"/>
    <origin rpy="0 0 1.5708" xyz="0.05 -0.55 1.335"/>
  </joint>
  <link name="cable_box">
    <inertial>
      <mass value="100"/>
      <origin xyz="0 0 0"/>
      <inertia ixx="1" ixy="0.0" ixz="0.0" iyy="1" iyz="0.0" izz="1"/>
    </inertial>
    <!-- <visual>
        <origin rpy="0 0 0" xyz="0 0 0"/>
        <geometry>
          <box size="0.08 0.08 0.4"/>
        </geometry>
        <material name="white">
          <color rgba="1.0 1.0 1.0 1.0"/>
        </material>
      </visual> -->
    <collision>
      <origin rpy="0 0 0" xyz="0 0 0"/>
      <geometry>
        <box size="0.08 0.08 0.4"/>
      </geometry>
    </collision>
  </link>
  <joint name="world_cable_box_joint" type="fixed">
    <parent link="world"/>
    <child link="cable_box"/>
    <origin rpy="0 0 0" xyz="0.35 0.47 1.35"/>
  </joint>
  <material name="gray">
    <color rgba="0.5 0.5 0.5 1.0"/>
  </material>
  <!-- <link name="${prefix}iiwa_base" type="fixed"/>

        <joint name="${prefix}iiwa_root_joint" type="fixed">
            <xacro:insert_block name="origin" />
            <parent link="${parent}"/>
            <child link="${prefix}iiwa_base"/>
        </joint> -->
  <joint name="iiwa7_base_joint" type="fixed">
    <origin rpy="0 0 0" xyz="0 0 0"/>
    <parent link="iiwa7_table_base"/>
    <child link="iiwa7_link_0"/>
  </joint>
  <link name="iiwa7_link_0">
    <visual>
      <origin rpy="0.0 0 0" xyz="0 0 0"/>
      <geometry>
        <mesh filename="package://iiwa7_description/meshes/iiwa7/visual/link_0.dae"/>
      </geometry>
    </visual>
    <collision>
      <origin rpy="0 0 0" xyz="0 0 0"/>
      <geometry>
        <mesh filename="package://iiwa7_description/meshes/iiwa7/collision/link_0.stl"/>
      </geometry>
    </collision>
    <inertial>
      <origin rpy="0 0 0" xyz="-0.1 0 0.07"/>
      <mass value="5"/>
      <inertia ixx="0.05" ixy="0" ixz="0" iyy="0.06" iyz="0" izz="0.03"/>
    </inertial>
    <self_collision_checking>
      <origin rpy="0 0 0" xyz="0 0 0"/>
      <geometry>
        <capsule length="0.25" radius="0.15"/>
      </geometry>
    </self_collision_checking>
  </link>
  <link name="iiwa7_link_1">
    <visual>
      <origin rpy="0 0 0" xyz="0 0 0.0075"/>
      <geometry>
        <mesh filename="package://iiwa7_description/meshes/iiwa7/visual/link_1.dae"/>
      </geometry>
    </visual>
    <collision>
      <origin rpy="0 0 0.0075" xyz="0 0 0.0075"/>
      <geometry>
        <mesh filename="package://iiwa7_description/meshes/iiwa7/collision/link_1.stl"/>
      </geometry>
    </collision>
    <inertial>
      <origin rpy="0 0 0" xyz="0 -0.03 0.12"/>
      <mass value="3.4525"/>
      <inertia ixx="0.02183" ixy="0" ixz="0" iyy="0.007703" iyz="-0.003887" izz="0.02083"/>
    </inertial>
  </link>
  <link name="iiwa7_link_2">
    <visual>
      <origin rpy="0 0 0" xyz="0 0 0"/>
      <geometry>
        <mesh filename="package://iiwa7_description/meshes/iiwa7/visual/link_2.dae"/>
      </geometry>
    </visual>
    <collision>
      <origin rpy="0 0 0" xyz="0 0 0"/>
      <geometry>
        <mesh filename="package://iiwa7_description/meshes/iiwa7/collision/link_2.stl"/>
      </geometry>
    </collision>
    <inertial>
      <origin rpy="0 0 0" xyz="0.0003 0.059 0.042"/>
      <mass value="3.4821"/>
      <inertia ixx="0.02076" ixy="0" ixz="-0.003626" iyy="0.02179" iyz="0" izz="0.00779"/>
    </inertial>
  </link>
  <link name="iiwa7_link_3">
    <visual>
      <origin rpy="0 0 0" xyz="0 0 -0.026"/>
      <geometry>
        <mesh filename="package://iiwa7_description/meshes/iiwa7/visual/link_3.dae"/>
      </geometry>
    </visual>
    <collision>
      <origin rpy="0 0 0" xyz="0 0 -0.026"/>
      <geometry>
        <mesh filename="package://iiwa7_description/meshes/iiwa7/collision/link_3.stl"/>
      </geometry>
    </collision>
    <inertial>
      <origin rpy="0 0 0" xyz="0 0.03 0.13"/>
      <mass value="4.05623"/>
      <inertia ixx="0.03204" ixy="0" ixz="0" iyy="0.00972" iyz="0.006227" izz="0.03042"/>
    </inertial>
  </link>
  <link name="iiwa7_link_4">
    <visual>
      <origin rpy="0 0 0" xyz="0 0 0"/>
      <geometry>
        <mesh filename="package://iiwa7_description/meshes/iiwa7/visual/link_4.dae"/>
      </geometry>
    </visual>
    <collision>
      <origin rpy="0 0 0" xyz="0 0 0"/>
      <geometry>
        <mesh filename="package://iiwa7_description/meshes/iiwa7/collision/link_4.stl"/>
      </geometry>
    </collision>
    <inertial>
      <origin rpy="0 0 0" xyz="0 0.067 0.034"/>
      <mass value="3.4822"/>
      <inertia ixx="0.02178" ixy="0" ixz="0" iyy="0.02075" iyz="-0.003625" izz="0.007785"/>
    </inertial>
  </link>
  <link name="iiwa7_link_5">
    <visual>
      <origin rpy="0 0 0" xyz="0 0 -0.026"/>
      <geometry>
        <mesh filename="package://iiwa7_description/meshes/iiwa7/visual/link_5.dae"/>
      </geometry>
    </visual>
    <collision>
      <origin rpy="0 0 0" xyz="0 0 -0.026"/>
      <geometry>
        <mesh filename="package://iiwa7_description/meshes/iiwa7/collision/link_5.stl"/>
      </geometry>
    </collision>
    <inertial>
      <origin rpy="0 0 0" xyz="0.0001 0.021 0.076"/>
      <mass value="2.1633"/>
      <inertia ixx="0.01287" ixy="0" ixz="0" iyy="0.005708" iyz="-0.003946" izz="0.01112"/>
    </inertial>
  </link>
  <link name="iiwa7_link_6">
    <visual>
      <origin rpy="0 0 0" xyz="0 0 0"/>
      <geometry>
        <mesh filename="package://iiwa7_description/meshes/iiwa7/visual/link_6.dae"/>
      </geometry>
    </visual>
    <collision>
      <origin rpy="0 0 0" xyz="0 0 0"/>
      <geometry>
        <mesh filename="package://iiwa7_description/meshes/iiwa7/collision/link_6.stl"/>
      </geometry>
    </collision>
    <inertial>
      <origin rpy="0 0 0" xyz="0 0.0006 0.0004"/>
      <mass value="2.3466"/>
      <inertia ixx="0.006509" ixy="0" ixz="0" iyy="0.006259" iyz="0.00031891" izz="0.004527"/>
    </inertial>
  </link>
  <link name="iiwa7_link_7">
    <visual>
      <origin rpy="0 0 0" xyz="0 0 -0.0005"/>
      <material name="gray"/>
      <geometry>
        <mesh filename="package://iiwa7_description/meshes/iiwa7/visual/link_7.stl"/>
      </geometry>
    </visual>
    <collision>
      <origin rpy="0 0 0" xyz="0 0 -0.0005"/>
      <geometry>
        <mesh filename="package://iiwa7_description/meshes/iiwa7/collision/link_7.stl"/>
      </geometry>
    </collision>
    <inertial>
      <origin rpy="0 0 0" xyz="0 0 0.02"/>
      <mass value="3.129"/>
      <inertia ixx="0.01464" ixy="0.0005912" ixz="0" iyy="0.01465" iyz="0" izz="0.002872"/>
    </inertial>
  </link>
  <link name="iiwa7_tool0"/>
  <joint name="iiwa7_joint_1" type="revolute">
    <origin rpy="0 0 0" xyz="0 0 0.15"/>
    <parent link="iiwa7_link_0"/>
    <child link="iiwa7_link_1"/>
    <axis xyz="0 0 1"/>
    <limit effort="176" lower="-2.9670597283903604" upper="2.9670597283903604" velocity="1.710422666954443"/>
    <safety_controller k_position="100" k_velocity="10" soft_lower_limit="-2.8187067419708423" soft_upper_limit="2.8187067419708423"/>
    <dynamics damping="0.5"/>
  </joint>
  <joint name="iiwa7_joint_2" type="revolute">
    <origin rpy="1.5707963267948966   0 3.141592653589793" xyz="0 0 0.19"/>
    <parent link="iiwa7_link_1"/>
    <child link="iiwa7_link_2"/>
    <axis xyz="0 0 1"/>
    <limit effort="176" lower="-2.0943951023931953" upper="2.0943951023931953" velocity="1.710422666954443"/>
    <safety_controller k_position="100" k_velocity="10" soft_lower_limit="-1.9896753472735356" soft_upper_limit="1.9896753472735356"/>
    <dynamics damping="0.5"/>
  </joint>
  <joint name="iiwa7_joint_3" type="revolute">
    <origin rpy="1.5707963267948966 0 3.141592653589793" xyz="0 0.21 0"/>
    <parent link="iiwa7_link_2"/>
    <child link="iiwa7_link_3"/>
    <axis xyz="0 0 1"/>
    <limit effort="110" lower="-2.9670597283903604" upper="2.9670597283903604" velocity="1.7453292519943295"/>
    <safety_controller k_position="100" k_velocity="10" soft_lower_limit="-2.8187067419708423" soft_upper_limit="2.8187067419708423"/>
    <dynamics damping="0.5"/>
  </joint>
  <joint name="iiwa7_joint_4" type="revolute">
    <origin rpy="1.5707963267948966 0 0" xyz="0 0 0.19"/>
    <parent link="iiwa7_link_3"/>
    <child link="iiwa7_link_4"/>
    <axis xyz="0 0 1"/>
    <limit effort="110" lower="-2.0943951023931953" upper="2.0943951023931953" velocity="2.2689280275926285"/>
    <safety_controller k_position="100" k_velocity="10" soft_lower_limit="-1.9896753472735356" soft_upper_limit="1.9896753472735356"/>
    <dynamics damping="0.5"/>
  </joint>
  <joint name="iiwa7_joint_5" type="revolute">
    <origin rpy="-1.5707963267948966 3.141592653589793 0" xyz="0 0.21 0"/>
    <parent link="iiwa7_link_4"/>
    <child link="iiwa7_link_5"/>
    <axis xyz="0 0 1"/>
    <limit effort="110" lower="-2.9670597283903604" upper="2.9670597283903604" velocity="2.443460952792061"/>
    <safety_controller k_position="100" k_velocity="10" soft_lower_limit="-2.8187067419708423" soft_upper_limit="2.8187067419708423"/>
    <dynamics damping="0.5"/>
  </joint>
  <joint name="iiwa7_joint_6" type="revolute">
    <origin rpy="1.5707963267948966 0 0" xyz="0 0.06070 0.19"/>
    <parent link="iiwa7_link_5"/>
    <child link="iiwa7_link_6"/>
    <axis xyz="0 0 1"/>
    <limit effort="40" lower="-2.0943951023931953" upper="2.0943951023931953" velocity="3.141592653589793"/>
    <safety_controller k_position="100" k_velocity="10" soft_lower_limit="-1.9896753472735356" soft_upper_limit="1.9896753472735356"/>
    <dynamics damping="0.5"/>
  </joint>
  <joint name="iiwa7_joint_7" type="revolute">
    <origin rpy="-1.5707963267948966 3.141592653589793 0" xyz="0 0.081 0.06070"/>
    <parent link="iiwa7_link_6"/>
    <child link="iiwa7_link_7"/>
    <axis xyz="0 0 1"/>
    <limit effort="40" lower="-3.0543261909900763" upper="3.0543261909900763" velocity="3.141592653589793"/>
    <safety_controller k_position="100" k_velocity="10" soft_lower_limit="-2.901609881440573" soft_upper_limit="2.901609881440573"/>
    <dynamics damping="0.5"/>
  </joint>
  <joint name="iiwa7_joint_7-tool0" type="fixed">
    <origin rpy="0 0 0" xyz="0 0 0.045"/>
    <parent link="iiwa7_link_7"/>
    <child link="iiwa7_tool0"/>
    <axis xyz="0 0 0"/>
  </joint>
  <ros2_control name="iiwaRobot" type="system">
    <hardware>
      <plugin>iiwa_hardware/IiwaFRIHardwareInterface</plugin>
      <param name="robot_ip">192.170.10.2</param>
      <param name="robot_port">30200</param>
      <param name="velocity_filter_cutoff_freq">40</param>
      <param name="torque_filter_cutoff_freq">40</param>
    </hardware>
    <joint name="iiwa7_joint_1">
      <param name="initial_position">0.0</param>
      <command_interface name="position"/>
      <param name="min">-2.96</param>
      <param name="max">2.96</param>
      <state_interface name="position"/>
      <state_interface name="velocity"/>
      <state_interface name="effort"/>
    </joint>
    <joint name="iiwa7_joint_2">
      <param name="initial_position">-0.7854</param>
      <command_interface name="position"/>
      <param name="min">-2.09</param>
      <param name="max">2.09</param>
      <state_interface name="position"/>
      <state_interface name="velocity"/>
      <state_interface name="effort"/>
    </joint>
    <joint name="iiwa7_joint_3">
      <param name="initial_position">0.0</param>
      <command_interface name="position"/>
      <param name="min">-2.96</param>
      <param name="max">2.96</param>
      <state_interface name="position"/>
      <state_interface name="velocity"/>
      <state_interface name="effort"/>
    </joint>
    <joint name="iiwa7_joint_4">
      <param name="initial_position">1.3962</param>
      <command_interface name="position"/>
      <param name="min">-2.09</param>
      <param name="max">2.09</param>
      <state_interface name="position"/>
      <state_interface name="velocity"/>
      <state_interface name="effort"/>
    </joint>
    <joint name="iiwa7_joint_5">
      <param name="initial_position">0.0</param>
      <command_interface name="position"/>
      <param name="min">-2.96</param>
      <param name="max">2.96</param>
      <state_interface name="position"/>
      <state_interface name="velocity"/>
      <state_interface name="effort"/>
    </joint>
    <joint name="iiwa7_joint_6">
      <param name="initial_position">0.6109</param>
      <command_interface name="position"/>
      <param name="min">-2.09</param>
      <param name="max">2.09</param>
      <state_interface name="position"/>
      <state_interface name="velocity"/>
      <state_interface name="effort"/>
    </joint>
    <joint name="iiwa7_joint_7">
      <param name="initial_position">0.0</param>
      <command_interface name="position"/>
      <param name="min">-3.05</param>
      <param name="max">3.05</param>
      <state_interface name="position"/>
      <state_interface name="velocity"/>
      <state_interface name="effort"/>
    </joint>
    <sensor name="external_torque_sensor">
      <state_interface name="external_torque.iiwa7_joint_1"/>
      <state_interface name="external_torque.iiwa7_joint_2"/>
      <state_interface name="external_torque.iiwa7_joint_3"/>
      <state_interface name="external_torque.iiwa7_joint_4"/>
      <state_interface name="external_torque.iiwa7_joint_5"/>
      <state_interface name="external_torque.iiwa7_joint_6"/>
      <state_interface name="external_torque.iiwa7_joint_7"/>
    </sensor>
  </ros2_control>
  <!-- ros_control plugin -->
  <gazebo>
    <plugin filename="libgazebo_ros2_control.so" name="gazebo_ros2_control">
      <parameters>/home/vishnu/ros_ws/colcon_kuka_ws/install/iiwa7_description/share/iiwa7_description/config/iiwa_controllers.yaml</parameters>
    </plugin>
  </gazebo>
  <!-- color -->
  <gazebo reference="iiwa7_link_0">
    <material>Gazebo/Grey</material>
    <mu1>0.2</mu1>
    <mu2>0.2</mu2>
  </gazebo>
  <!-- Link1 -->
  <gazebo reference="iiwa7_link_1">
    <material>Gazebo/Orange</material>
    <mu1>0.2</mu1>
    <mu2>0.2</mu2>
  </gazebo>
  <!-- Link2 -->
  <gazebo reference="iiwa7_link_2">
    <material>Gazebo/Orange</material>
    <mu1>0.2</mu1>
    <mu2>0.2</mu2>
  </gazebo>
  <!-- Link3 -->
  <gazebo reference="iiwa7_link_3">
    <material>Gazebo/Orange</material>
    <mu1>0.2</mu1>
    <mu2>0.2</mu2>
  </gazebo>
  <!-- Link4 -->
  <gazebo reference="iiwa7_link_4">
    <material>Gazebo/Orange</material>
    <mu1>0.2</mu1>
    <mu2>0.2</mu2>
  </gazebo>
  <!-- Link5 -->
  <gazebo reference="iiwa7_link_5">
    <material>Gazebo/Orange</material>
    <mu1>0.2</mu1>
    <mu2>0.2</mu2>
  </gazebo>
  <!-- Link6 -->
  <gazebo reference="iiwa7_link_6">
    <material>Gazebo/Orange</material>
    <mu1>0.2</mu1>
    <mu2>0.2</mu2>
  </gazebo>
  <!-- Link7 -->
  <gazebo reference="iiwa7_link_7">
    <material>Gazebo/Grey</material>
    <mu1>0.2</mu1>
    <mu2>0.2</mu2>
  </gazebo>
  <joint name="wsg50_gripper_joint" type="fixed">
    <origin rpy="0 0 0.785398" xyz="0 0 0.037"/>
    <parent link="iiwa7_tool0"/>
    <child link="wsg50_base_link"/>
  </joint>
  <link name="wsg50_base_link">
    <inertial>
      <mass value="0.25"/>
      <origin xyz="0 0 0"/>
      <inertia ixx="1.0" ixy="0.0" ixz="0.0" iyy="1.0" iyz="0.0" izz="1.0"/>
    </inertial>
    <visual>
      <origin rpy="0 0 0" xyz="0.0 0 0"/>
      <geometry>
        <box size="0.20 0.09 0.0735"/>
        <!-- <mesh filename="package://wsg50_description/meshes/WSG50_110.stl" scale="1 1 1"/> -->
      </geometry>
      <material name="grey">
        <color rgba="0.5 0.5 0.5 1"/>
      </material>
    </visual>
    <collision>
      <origin rpy="0 0 0" xyz="0.0 0 0"/>
      <geometry>
        <box size="0.25 0.09 0.0735"/>
        <!-- <mesh filename="package://wsg50_description/meshes/WSG50_110.stl" scale="1 1 1"/> -->
      </geometry>
    </collision>
  </link>
  <gazebo reference="wsg50_base_link">
    <material>Gazebo/Grey</material>
    <turnGravityOff>false</turnGravityOff>
  </gazebo>
  <joint name="wsg50_center_joint" type="fixed">
    <origin rpy="0 0 0" xyz="0 0 0.023"/>
    <!--origin xyz="-0.0067 0 0.049" rpy="0 0 0" /-->
    <parent link="wsg50_base_link"/>
    <child link="wsg50_center"/>
  </joint>
  <link name="wsg50_center"/>
  <!-- GRIPPER LEFT -->
  <link name="wsg50_gripper_left">
    <inertial>
      <mass value="0.1"/>
      <origin xyz="0 0 0"/>
      <inertia ixx="1.0" ixy="0.0" ixz="0.0" iyy="1.0" iyz="0.0" izz="1.0"/>
    </inertial>
    <visual>
      <origin rpy="0 0 0" xyz="0 0 0"/>
      <material name="grey"/>
      <geometry>
        <mesh filename="package://wsg50_description/meshes/kuka_gripper_2.dae"/>
      </geometry>
    </visual>
    <collision>
      <origin rpy="0 0 0" xyz="0 0 0"/>
      <geometry>
        <mesh filename="package://wsg50_description/meshes/kuka_gripper_2.stl"/>
      </geometry>
    </collision>
    <contact_coefficients kd="1.0" kp="1000.0" mu="0"/>
  </link>
  <gazebo reference="wsg50_gripper_left">
    <material>Gazebo/Blue</material>
    <turnGravityOff>false</turnGravityOff>
  </gazebo>
  <joint name="wsg50_finger_left_joint" type="fixed">
    <limit effort="1.0" lower="-0.055" upper="-0.0027" velocity="1.0"/>
    <origin rpy="3.1457 0 3.1457" xyz="0.08 0 0.12"/>
    <!--origin xyz="-0.0067 0 0.049" rpy="0 0 0" /-->
    <parent link="wsg50_base_link"/>
    <child link="wsg50_gripper_left"/>
    <dynamics damping="100" friction="100"/>
    <axis xyz="1 0 0"/>
    <limit effort="100" velocity="100"/>
  </joint>
  <!-- GRIPPER RIGHT -->
  <link name="wsg50_gripper_right">
    <inertial>
      <mass value="0.1"/>
      <origin xyz="0 0 0"/>
      <inertia ixx="1.0" ixy="0.0" ixz="0.0" iyy="1.0" iyz="0.0" izz="1.0"/>
    </inertial>
    <visual>
      <origin rpy="0 0 0" xyz="0.0 0 0"/>
      <material name="grey"/>
      <geometry>
        <mesh filename="package://wsg50_description/meshes/kuka_gripper_2.dae"/>
      </geometry>
    </visual>
    <collision>
      <origin rpy="0 0 0" xyz="0 0 0"/>
      <geometry>
        <mesh filename="package://wsg50_description/meshes/kuka_gripper_2.stl"/>
      </geometry>
    </collision>
    <contact_coefficients kd="1.0" kp="1000.0" mu="0"/>
  </link>
  <gazebo reference="gripper_right">
    <material>Gazebo/White</material>
    <turnGravityOff>false</turnGravityOff>
  </gazebo>
  <joint name="wsg50_finger_right_joint" type="fixed">
    <limit effort="1.0" lower="0.0027" upper="0.055" velocity="1.0"/>
    <origin rpy="3.14159 0 0" xyz="-0.08 0 0.12"/>
    <parent link="wsg50_base_link"/>
    <child link="wsg50_gripper_right"/>
    <axis xyz="-1 0 0"/>
    <dynamics damping="100" friction="100"/>
    <limit effort="100" velocity="100"/>
  </joint>
  <!-- <link name="object">
            <inertial>
                <mass value="100"/>
                <origin xyz="0 0 0" />
                <inertia  ixx="1" ixy="0.0"  ixz="0.0"  iyy="1"  iyz="0.0"  izz="1" />
            </inertial>
            <visual>
                <origin rpy="0 0 0" xyz="0 0 0"/>
                <geometry>
                    <box size="0.08 0.08 0.4"/>
                </geometry>
                <material name="white">
                    <color rgba="1.0 1.0 1.0 1.0"/>
                </material>
            </visual>
            <collision>
                <origin rpy="0 0 0" xyz="0 0 0"/>
                <geometry>
                    <box size="0.08 0.08 0.4"/>
                </geometry>
            </collision>
        </link> -->
</robot>
